Workbook

Sheet Como usar
A1: CHECKLIST DE AUDITORIA DE E-COMMERCE — V4
A2: Como usar
A5: Para que serve
A6: Diagnosticar um e-commerce ANTES de rodar mídia e auditar projetos em andamento. Cobre Tecnologia, Design/UX, Marketing e Pós-venda/Encantamento. Une o checklist da unidade (CRO, UX, pós-venda) com as lições do benchmark Make Life (checkout, frete, tracking, aquisição).
A8: Passo a passo
A9: 1. Teste de compra REAL é obrigatório: compre de verdade — 1, 2 e 5+ produtos, cartão (à vista e parcelado), Pix e boleto, CEPs diferentes, no desktop e no mobile.
A10: 2. Cada item tem a coluna "Como executar" com o passo a passo. Onde aparece "peça à IA", use a IA para acelerar (descrições, FAQ, roteiros, UTMs, copy).
A11: 3. Marque a coluna ✓ ao verificar e escolha o Status no menu (OK / Ajustar / Crítico / N/A) — a cor muda sozinha.
A12: 4. Gere o entregável duplo: lista de problemas para o time de execução + itens que viram serviço adicional (upsell) para o cliente.
A14: Legenda — Criticidade
A15: Crítico = bloqueia venda; resolver antes de escalar mídia. Importante = impacta conversão. Bom ter = otimização.
A16: Legenda — Status
... A20: Admin da plataforma · Hospedagem/DNS · Gateway de pagamento · GA4 · Search Console · GTM · Meta Business (pixel/catálogo/CAPI) · Google Ads · Merchant Center · CRM/automação · Plataforma de checkout (IAMP/Car Panda).

Sheet 1. Tecnologia
A1: CHECKLIST DE AUDITORIA DE E-COMMERCE
A2: V4 Company · 1. Tecnologia
A3: ✓ | B3: Item | C3: Como executar (passo a passo) | D3: Criticidade | E3: Status | F3: Observações
A4: 1.1 Infraestrutura, segurança e legal
B5: HTTPS/SSL ativo e válido em todas as páginas | C5: No painel da hospedagem ative o certificado SSL (Let's Encrypt é grátis) e force HTTPS no site todo. Teste em whynopadlock.com para achar "mixed content". | D5: Crítico | E5: Pendente
B6: Pop-up de consentimento de cookies (LGPD — obrigatório) | C6: Instale um plugin/banner de cookies (ex.: Complianz, Cookiebot) com aceite e link da política de privacidade. Obrigatório por lei. | D6: Crítico | E6: Pendente
B7: CNPJ visível em todas as páginas (obrigatório) | C7: Inclua o CNPJ + razão social no rodapé do tema, que aparece em todas as páginas. | D7: Crítico | E7: Pendente
B8: Domínio próprio + e-mail profissional no domínio | C8: Confirme domínio próprio; configure e-mail no domínio (Google Workspace/Zoho) em vez de @gmail. | D8: Importante | E8: Pendente
B9: Plataforma e versão identificadas e suportadas | C9: Identifique a plataforma (WooCommerce/Shopify/Tray/Nuvemshop) e a versão; confirme que está atualizada e com suporte. | D9: Importante | E9: Pendente
B10: (WooCommerce) Plugins atualizados, sem quebrados/órfãos | C10: Liste os plugins; atualize, remova os sem uso e teste se algum quebra o site. Menos plugin = site mais leve. | D10: Importante | E10: Pendente
B11: Backup automático + ambiente de teste (staging) | C11: Ative backup automático (plugin/host) e crie um staging para testar mudanças antes de subir no ar. | D11: Importante | E11: Pendente
A12: 1.2 Performance (velocidade)
B13: Core Web Vitals OK (LCP, CLS, INP) | C13: Rode PageSpeed Insights e GTmetrix; foque em LCP < 2,5s. Liste os gargalos apontados. | D13: Importante | E13: Pendente
B14: Imagens otimizadas (webp, peso, lazy load) | C14: Converta imagens para webp e ative compressão + lazy load (plugin ou CDN). Peça à IA para gerar os alt-texts. | D14: Importante | E14: Pendente
B15: Cache + CDN ativos (Cloudflare e afins) | C15: Ative cache na plataforma e coloque um CDN (Cloudflare grátis) na frente do site. | D15: Bom ter | E15: Pendente
B16: Carregamento rápido no mobile | C16: Teste a home e a PDP no 4G real (não só wi-fi). Compare a velocidade do mobile com a do desktop. | D16: Importante | E16: Pendente
A17: 1.3 Checkout e pagamento
B18: Teste de compra real ponta a ponta concluído | C18: Faça um pedido de verdade: 1 produto e depois 5; pague com cartão (à vista e parcelado), Pix e boleto. Anote tudo que falhar. | D18: Crítico | E18: Pendente
B19: TODOS os métodos aprovando: cartão, Pix e boleto | C19: Confirme que cartão de crédito está APROVANDO (não só Pix). Se só Pix passa, há erro no gateway — resolver antes de escalar mídia. | D19: Crítico | E19: Pendente
B20: Gateway/adquirente configurado | C20: Verifique o gateway (IAMP, Car Panda, Mercado Pago, Pagar.me). Se o nativo dá problema, migrar para checkout pronto resolve rápido. | D20: Importante | E20: Pendente
B21: Checkout multi-etapa com salvamento de dados parciais | C21: Garanta etapas (dados → entrega → pagamento) e que dados parciais são salvos — sem isso não há recuperação de carrinho. | D21: Crítico | E21: Pendente
B22: Parcelamento configurado (parcelas, juros, mínimo) | C22: Defina nº de parcelas, juros e valor mínimo de parcela; teste no checkout. | D22: Importante | E22: Pendente
B23: Checkout testado e funcional no mobile | C23: Repita a compra-teste pelo celular; a maioria do tráfego é mobile. | D23: Crítico | E23: Pendente
B24: Selos de segurança visíveis no checkout | C24: Adicione selos (SSL, bandeiras, site seguro) na etapa de pagamento. | D24: Bom ter | E24: Pendente
A25: 1.4 Frete e logística
B26: Frete calculado por PEDIDO, não por unidade | C26: Adicione 5 itens iguais e cheque se o frete soma 5x (erro) ou cobra 1 frete (certo). Corrija a regra de caixa/peso. | D26: Crítico | E26: Pendente
B27: Teste de carrinho com 1, 2, 5 e 10 produtos | C27: Monte carrinhos com quantidades diferentes e confira o frete e o total em cada um. | D27: Crítico | E27: Pendente
B28: Teste de frete para múltiplas regiões/CEPs | C28: Simule CEP do Sul, Sudeste, Norte e Nordeste; veja se o valor faz sentido. | D28: Importante | E28: Pendente
B29: Integração com transportadora/Melhor Envio | C29: Confirme integração ativa (Correios/Melhor Envio/transportadora) puxando preço e prazo automaticamente. | D29: Importante | E29: Pendente
B30: Frete grátis condicional configurável | C30: Configure frete grátis acima de um valor X (decida com base no ticket médio). | D30: Importante | E30: Pendente
B31: Prazo de entrega exibido ao cliente | C31: Garanta que o prazo aparece na PDP e no checkout. | D31: Bom ter | E31: Pendente
A32: 1.5 Catálogo / produtos (técnico)
B33: Cadastro completo: SKU, estoque, variações, peso e dimensões | C33: Revise o cadastro — peso/dimensões erradas quebram o frete; variações faltando travam a compra. | D33: Importante | E33: Pendente
B34: Controle de estoque sincronizado | C34: Confirme que produto vendido/esgotado sai do catálogo automaticamente (sem vender o que não existe). | D34: Crítico | E34: Pendente
B35: Produtos esgotados tratados | C35: Defina o que acontece no esgotado: ocultar ou "avise-me quando chegar". | D35: Importante | E35: Pendente
B36: URLs amigáveis; sem 404; redirects de URLs antigas | C36: Rode um verificador de links quebrados; crie redirect 301 das URLs antigas para as novas. | D36: Bom ter | E36: Pendente
A37: 1.6 Rastreamento / dados
B38: Pixel Meta disparando (ViewContent, AddToCart, InitiateCheckout, Purchase c/ valor) | C38: Instale o pixel e confirme os eventos no Meta Events Manager, com valor no Purchase. | D38: Crítico | E38: Pendente
B39: API de Conversões (CAPI) da Meta configurada | C39: Ative a CAPI (via plugin/Conversions API Gateway) para não perder dados por bloqueio de cookie. | D39: Importante | E39: Pendente
B40: GA4 com eventos de e-commerce (purchase + value) | C40: Configure GA4 e-commerce e valide add_to_cart, begin_checkout e purchase no DebugView. | D40: Crítico | E40: Pendente
...

Sheet 2. Design e UX
A1: CHECKLIST DE AUDITORIA DE E-COMMERCE
A2: V4 Company · 2. Design e UX
A3: ✓ | B3: Item | C3: Como executar (passo a passo) | D3: Criticidade | E3: Status | F3: Observações
A4: 2.1 Identidade visual e marca
B5: Logo bem desenhado + favicon na aba do navegador | C5: Use logo profissional e configure o favicon (ícone na aba). Em nicho de ticket alto, visual ruim derruba confiança. | D5: Importante | E5: Pendente
B6: Paleta e tipografia consistentes e alinhadas à marca | C6: Padronize cores e fontes em todo o site; siga o manual da marca se houver. | D6: Importante | E6: Pendente
B7: Coerência visual entre home, PDP, carrinho e checkout | C7: Navegue pelas 4 telas e confira se parecem o mesmo site. | D7: Bom ter | E7: Pendente
A8: 2.2 Home e navegação
B9: Proposta de valor clara above the fold | C9: No topo da home deixe claro o que vende, pra quem e o diferencial — sem precisar rolar. | D9: Importante | E9: Pendente
B10: Menu/categorias claros + busca interna no topo | C10: Organize categorias e coloque campo de busca visível no topo. Peça à IA para sugerir a arquitetura de categorias. | D10: Importante | E10: Pendente
B11: Breadcrumbs (caminho de navegação) em cada página | C11: Ative breadcrumbs (Início > Categoria > Produto) para o cliente se localizar e ajudar o SEO. | D11: Importante | E11: Pendente
B12: Carrinho visível no topo em todas as páginas | C12: Garanta o ícone de carrinho fixo no topo, com contador de itens. | D12: Importante | E12: Pendente
B13: Banners/destaques apontando para ofertas/produtos certos | C13: Use banners na home para mais vendidos, lançamentos e promoção ativa. | D13: Bom ter | E13: Pendente
A14: 2.3 Página de produto (PDP)
B15: Fotos profissionais (ângulos, zoom, produto em uso) | C15: Garanta várias fotos com zoom e contexto de uso. Sem foto boa não há conversão. | D15: Crítico | E15: Pendente
B16: Vídeo de produto | C16: Adicione vídeo curto mostrando o produto funcionando/em uso. | D16: Importante | E16: Pendente
B17: Descrição clara: benefício primeiro, especificação depois | C17: Reescreva as descrições: 1ª linha = benefício; depois specs. Use a IA para gerar a partir das especificações. | D17: Importante | E17: Pendente
B18: Preço, parcelamento e frete visíveis na PDP | C18: Mostre preço, em quantas vezes e o cálculo de frete na própria página do produto. | D18: Importante | E18: Pendente
B19: CTA de compra destacado e acima da dobra | C19: Botão "comprar/adicionar" em cor de destaque, visível sem rolar. | D19: Crítico | E19: Pendente
B20: Prova social (avaliações, depoimentos, selos, nº de vendas) | C20: Ative avaliações de clientes e exiba depoimentos/selos na PDP. | D20: Importante | E20: Pendente
B21: Variações (tamanho/cor/kit) claras e fáceis de selecionar | C21: Teste a seleção de variação; deixe claro o que está selecionado. | D21: Importante | E21: Pendente
B22: Cross-sell / "compre junto" na PDP | C22: Configure produtos relacionados e combos na página do produto. | D22: Importante | E22: Pendente
B23: Gatilhos de urgência/escassez quando reais | C23: Use "últimas unidades"/contador só quando for verdade — sem alarmismo. | D23: Bom ter | E23: Pendente
A24: 2.4 Carrinho e checkout (UX)
B25: Carrinho claro e fácil de editar | C25: Confira se dá para alterar quantidade e remover item facilmente. | D25: Importante | E25: Pendente
B26: Mínimo de fricção no checkout (só campos necessários) | C26: Reduza campos ao essencial; cada campo a mais derruba conversão. | D26: Crítico | E26: Pendente
B27: Guest checkout (comprar sem criar conta) | C27: Permita finalizar sem obrigar criar conta. | D27: Importante | E27: Pendente
B28: Barra de progresso de frete grátis | C28: Mostre "faltam R$X para o frete grátis" no carrinho/checkout. | D28: Importante | E28: Pendente
B29: Order bump / upsell no checkout | C29: Ofereça um item complementar de baixo valor no momento do pagamento. | D29: Importante | E29: Pendente
B30: Campo de cupom / código promocional | C30: Inclua campo de cupom no checkout e teste um código. | D30: Importante | E30: Pendente
B31: Botão de finalizar no topo e no rodapé das páginas | C31: Garanta o botão de checkout acessível no topo e no fim. | D31: Bom ter | E31: Pendente
A32: 2.5 Confiança e credibilidade
B33: Páginas: Sobre, Contato, Trocas/Devoluções, Privacidade, FAQ | C33: Crie/revise essas páginas. Peça à IA para gerar um FAQ a partir das dúvidas mais comuns do atendimento. | D33: Importante | E33: Pendente
B34: Selos (SSL, Reclame Aqui, pagamentos, Google) | C34: Exiba os selos no rodapé e no checkout. | D34: Bom ter | E34: Pendente
B35: Depoimentos/reviews reais (não genéricos) | C35: Colete prints/áudios de clientes reais e publique. | D35: Importante | E35: Pendente
B36: Chat ao vivo / atendimento no site (WhatsApp visível) | C36: Adicione chat/WhatsApp visível para tirar dúvida na hora da compra. | D36: Importante | E36: Pendente
A37: 2.6 Mobile UX
B38: Layout responsivo real (não só "encolhido") | C38: Abra cada página no celular e veja se está pensada para mobile, não só reduzida. | D38: Crítico | E38: Pendente
B39: Botões clicáveis sem zoom; formulários fáceis no mobile | C39: Teste preencher e clicar com o dedo, sem precisar dar zoom. | D39: Importante | E39: Pendente
B40: Checkout mobile testado de ponta a ponta | C40: Finalize uma compra real pelo celular. | D40: Crítico | E40: Pendente
...

Sheet 3. Marketing e Aquisição
A1: CHECKLIST DE AUDITORIA DE E-COMMERCE
A2: V4 Company · 3. Marketing e Aquisição
A3: ✓ | B3: Item | C3: Como executar (passo a passo) | D3: Criticidade | E3: Status | F3: Observações
A4: 3.1 Estratégia de canal
B5: Mapear: produto tem volume de busca (Google) ou exige descoberta (Meta) | C5: Pesquise o volume das palavras no Planejador do Google. Sem volume = comece pelo Meta (descoberta no feed). Lição Make Life. | D5: Crítico | E5: Pendente
B6: Restrições de política do nicho verificadas (Google e Meta) | C6: Cheque se o nicho (saúde, suplemento, etc.) tem termos/produtos restritos antes de planejar. | D6: Importante | E6: Pendente
B7: Canal primário definido pelo nicho, não por padrão | C7: Defina onde colocar o dinheiro com base no nicho/maturidade, não "Google porque sempre foi". | D7: Importante | E7: Pendente
A8: 3.2 Oferta e produto
B9: Ticket médio real mapeado (CPA ≤ ~50% do ticket médio) | C9: Calcule o ticket médio real (não o do produto âncora) e use como teto de CPA. | D9: Crítico | E9: Pendente
B10: Produto âncora definido (margem + saída + segmentação) | C10: Escolha o produto de entrada por margem boa, saída e facilidade de segmentar o público. | D10: Importante | E10: Pendente
B11: Ticket baixo (≤R$40) vendido em kit/bundle, não unitário | C11: Monte kits para produtos baratos; no tráfego unitário o CPA não fecha. Lição Make Life (Chuca Pop). | D11: Crítico | E11: Pendente
B12: Alavancas de oferta: frete grátis, cashback, cupom, kit | C12: Defina 1-2 alavancas principais e teste no anúncio/checkout. | D12: Importante | E12: Pendente
B13: Desconto progressivo (compre mais, ganhe mais) | C13: Configure desconto por quantidade ou acima de valor X para subir o ticket. | D13: Bom ter | E13: Pendente
B14: Cross-sell / upsell mapeados (pares complementares) | C14: Liste pares de produtos que combinam e configure as ofertas. | D14: Importante | E14: Pendente
A15: 3.3 Criativos e conteúdo
B16: Rosto humano de quem acredita no produto priorizado vs. IA | C16: Priorize vídeos com o dono/especialista. Lição Make Life: rosto venceu IA em 6/6 testes. | D16: Crítico | E16: Pendente
B17: Vídeos educativos de topo de funil (problema → solução) | C17: Roteirize vídeos curtos: sintoma/dor → solução com o produto. Peça à IA para gerar variações de roteiro. | D17: Importante | E17: Pendente
B18: Cadência de produção garantida (ter 2º rosto/criador) | C18: Defina meta de criativos novos/semana e um 2º criador para não depender de 1 pessoa. | D18: Crítico | E18: Pendente
B19: Network → anúncio: fechar o loop (permissão + edição + veiculação) | C19: Se o cliente tem parceiros/médicos/influencers, peça permissão de uso e leve os vídeos ao anúncio. Lição Make Life. | D19: Importante | E19: Pendente
B20: Distribuição orgânica (TikTok, YouTube/Shorts, Merchant) | C20: Poste todo vídeo de anúncio também nos canais orgânicos — alcance extra sem custo de produção. | D20: Importante | E20: Pendente
B21: Prova social usada como criativo | C21: Transforme prints/depoimentos de clientes em anúncio. | D21: Bom ter | E21: Pendente
A22: 3.4 Funil e mídia
B23: Estrutura de campanha por etapa (topo/meio/fundo) | C23: Separe campanhas de descoberta, consideração e conversão. | D23: Importante | E23: Pendente
B24: Públicos validados antes de escalar | C24: Teste públicos em verba baixa; só escale os que provaram resultado. Lição Make Life. | D24: Importante | E24: Pendente
B25: Remarketing ativo (visitantes, carrinho, base) | C25: Crie públicos de remarketing (site, carrinho, base) e campanhas para eles. | D25: Importante | E25: Pendente
B26: Verba de teste separada da verba de escala | C26: Reserve um % fixo para testar criativos novos, separado da campanha principal. | D26: Importante | E26: Pendente
B27: TikTok Shop / afiliados avaliado (forte p/ ticket baixo) | C27: Avalie TikTok Shop + afiliados — bom para produto barato que não fecha em mídia paga. | D27: Bom ter | E27: Pendente
A28: 3.5 SEO e orgânico
B29: SEO on-page (títulos, meta descrições, URLs, headings) | C29: Otimize título, meta e H1 das principais páginas/produtos. Use a IA para gerar em escala a partir das specs. | D29: Importante | E29: Pendente
B30: Blog/conteúdo de topo de funil (quando faz sentido) | C30: Crie conteúdo que responde dúvidas do público e linka para os produtos. | D30: Bom ter | E30: Pendente
B31: Google Meu Negócio otimizado (se houver loja física) | C31: Complete o perfil, fotos, horário e peça avaliações. | D31: Bom ter | E31: Pendente
B32: Merchant Center gerando alcance orgânico | C32: Mantenha o feed saudável — gera tráfego orgânico de Shopping. | D32: Bom ter | E32: Pendente

Sheet 4. Pós-venda e Encantamento
A1: CHECKLIST DE AUDITORIA DE E-COMMERCE
A2: V4 Company · 4. Pós-venda e Encantamento
A3: ✓ | B3: Item | C3: Como executar (passo a passo) | D3: Criticidade | E3: Status | F3: Observações
A4: 4.1 Confirmação e acompanhamento do pedido
B5: Mensagem de boas-vindas/confirmação com prazo e passo a passo | C5: Assim que a compra é feita, envie (e-mail/WhatsApp) confirmando, com prazo e o que acontece a seguir. | D5: Importante | E5: Pendente
B6: Notificações automáticas de status do pedido / rastreio | C6: Configure avisos a cada etapa (pago, enviado, a caminho) com link de rastreio. | D6: Importante | E6: Pendente
B7: Nº do pedido, link de rastreio e opção de cancelar | C7: Garanta que o cliente vê o nº do pedido, rastreia o envio e consegue cancelar/abrir suporte. | D7: Importante | E7: Pendente
A8: 4.2 Retenção, recompra e LTV
B9: Recuperação de carrinho rodando (e-mail/SMS/WhatsApp) | C9: Ative a sequência de carrinho abandonado e meça a recuperação. Lição Make Life: 93% abandonavam na entrega (frete). | D9: Crítico | E9: Pendente
B10: Fluxo de fidelização no ciclo de recompra do produto | C10: Programe o follow-up de recompra para o ciclo do produto (ex.: 20-30 dias após a compra). | D10: Importante | E10: Pendente
B11: Follow-up 1-2 semanas após a entrega | C11: Mensagem perguntando como foi o produto + abrir espaço para dúvida/suporte. | D11: Importante | E11: Pendente
B12: Pedido de avaliação/review | C12: Peça review após a entrega (e-mail/WhatsApp), de preferência com incentivo. | D12: Importante | E12: Pendente
B13: Cupom de reativação se não recompra em X meses | C13: Dispare cupom para quem não volta há alguns meses. Peça à IA para escrever a copy. | D13: Importante | E13: Pendente
B14: E-mail de cross-sell para a base (produto A → produto B) | C14: Mapeie quem comprou A e ofereça B dias depois. Cadência pode ser agressiva (é base quente). | D14: Importante | E14: Pendente
B15: LTV sendo calculado | C15: Acompanhe recompra e calcule o LTV (precisa de 3-4 meses de dado limpo). | D15: Bom ter | E15: Pendente
B16: Programa de fidelidade / vale-presente | C16: Avalie programa de pontos/fidelidade e venda de vale-presente. | D16: Bom ter | E16: Pendente
B17: Programa de indicação | C17: Crie incentivo para cliente indicar (cupom para os dois). | D17: Bom ter | E17: Pendente
A18: 4.3 Encantamento (experiência que gera recompra e indicação)
B19: Vídeo/foto do produto sendo preparado e embalado | C19: Grave o preparo/embalagem e envie ao cliente — gera conexão e expectativa. | D19: Bom ter | E19: Pendente
B20: Bilhete/mensagem personalizada na embalagem | C20: Inclua um cartão com mensagem; se possível, personalizado pelo perfil/rede social do cliente. | D20: Bom ter | E20: Pendente
B21: Cupom personalizado para cliente de ticket alto | C21: Para quem comprou acima de X, envie cupom com o nome dele ("cliente especial recebe cupom especial"). | D21: Bom ter | E21: Pendente
B22: Identidade sensorial na embalagem (cheiro/unboxing) | C22: Use uma fragrância/embalagem que represente a marca — eleva a experiência de unboxing. | D22: Bom ter | E22: Pendente
B23: Acesso antecipado a novidades para quem já é cliente | C23: Ofereça lançamentos/novidades em primeira mão à base. | D23: Bom ter | E23: Pendente

Sheet Resumo
A1: RESUMO DA AUDITORIA
A2: V4 Company · preenche automaticamente conforme o Status das abas
A3: Frente | B3: Itens | C3: OK | D3: Ajustar | E3: Crítico | F3: Pendentes
A4: 1. Tecnologia | B4: =COUNTIF('1. Tecnologia'!D:D,"Crítico")+COUNTIF('1. Tecnologia'!D:D,"Importante")+COUNTIF('1. Tecnologia'!D:D,"Bom ter") | C4: =COUNTIF('1. Tecnologia'!E:E,"OK") | D4: =COUNTIF('1. Tecnologia'!E:E,"Ajustar") | E4: =COUNTIF('1. Tecnologia'!E:E,"Crítico") | F4: =COUNTIF('1. Tecnologia'!E:E,"Pendente")
A5: 2. Design e UX | B5: =COUNTIF('2. Design e UX'!D:D,"Crítico")+COUNTIF('2. Design e UX'!D:D,"Importante")+COUNTIF('2. Design e UX'!D:D,"Bom ter") | C5: =COUNTIF('2. Design e UX'!E:E,"OK") | D5: =COUNTIF('2. Design e UX'!E:E,"Ajustar") | E5: =COUNTIF('2. Design e UX'!E:E,"Crítico") | F5: =COUNTIF('2. Design e UX'!E:E,"Pendente")
A6: 3. Marketing e Aquisição | B6: =COUNTIF('3. Marketing e Aquisição'!D:D,"Crítico")+COUNTIF('3. Marketing e Aquisição'!D:D,"Importante")+COUNTIF('3. Marketing e Aquisição'!D:D,"Bom ter") | C6: =COUNTIF('3. Marketing e Aquisição'!E:E,"OK") | D6: =COUNTIF('3. Marketing e Aquisição'!E:E,"Ajustar") | E6: =COUNTIF('3. Marketing e Aquisição'!E:E,"Crítico") | F6: =COUNTIF('3. Marketing e Aquisição'!E:E,"Pendente")
A7: 4. Pós-venda e Encantamento | B7: =COUNTIF('4. Pós-venda e Encantamento'!D:D,"Crítico")+COUNTIF('4. Pós-venda e Encantamento'!D:D,"Importante")+COUNTIF('4. Pós-venda e Encantamento'!D:D,"Bom ter") | C7: =COUNTIF('4. Pós-venda e Encantamento'!E:E,"OK") | D7: =COUNTIF('4. Pós-venda e Encantamento'!E:E,"Ajustar") | E7: =COUNTIF('4. Pós-venda e Encantamento'!E:E,"Crítico") | F7: =COUNTIF('4. Pós-venda e Encantamento'!E:E,"Pendente")
A8: TOTAL | B8: =SUM(B4:B7) | C8: =SUM(C4:C7) | D8: =SUM(D4:D7) | E8: =SUM(E4:E7) | F8: =SUM(F4:F7)
A11: Top 3 bloqueadores antes de escalar mídia:
A12: 1.
A13: 2.
A14: 3.
A16: Itens recomendados como serviço adicional (upsell) ao cliente:
A17: -
A18: -
A19: -

Sheet _Listas
A1: Pendente | B1: ✓
A2: OK
A3: Ajustar
A4: Crítico
A5: N/A
